Workbook

Sheet 1.Cover Page
B1: FBA Dynamics 365 - Data Quality Assesment
B3: Module | C3: Accounts Receivable (AR)
B5: Prepared by | C5: Reyhaneh Hajili
B7: Date | C7: 28/09/2025
B9: Version | C9: 2.1
B11: Tools Used | C11: Microsoft Excel, Pivot Table
B13: This Excel workbook is an integral part of the FBA Dynamics 365 Data Quality Report (V2.1). All data validations, logs, and KPI, are synchronized with the final Word documentation.

Sheet 2.Raw Data_original
A1: CustomerID | B1: CustomerName | C1: InvoiceDate | D1: Amount_IRR | E1: PaymentDate | F1: CheckKey-1 | G1: CheckKey-2 | H1: CheckIDName | I1: CheckPaymentData
A2: C002 | B2: Sara Market | C2: 45677 | D2: 500000 | E2: 45958 | F2: =$A2&"-"&TEXT( $C2,"yyyy-mm-dd") -> C002-2025-01-20 | G2: =IF(COUNTIF($F$2:$F$42,F2)>1, "Duplicate", "Ok") -> Ok | H2: =IF(B2 =VLOOKUP($A2,$A$2:$B$42,2,FALSE), "OK", "Mismatch") -> OK | I2: =IF(C2>E2, "Inconsistent", "OK") -> OK
A3: C002 | B3: Sara Market | C3: 2025-09-03 | D3: 100000 | E3: 45904 | F3: =$A3&"-"&TEXT( $C3,"yyyy-mm-dd") -> C002-2025-09-03 | G3: =IF(COUNTIF($F$2:$F$42,F3)>1, "Duplicate", "Ok") -> Ok | H3: =IF(B3 =VLOOKUP($A3,$A$2:$B$42,2,FALSE), "OK", "Mismatch") -> OK | I3: =IF(C3>E3, "Inconsistent", "OK") -> Inconsistent
A4: C002 | B4: Reza Shop | C4: 45768 | D4: 1200000 | E4: 45891 | F4: =$A4&"-"&TEXT( $C4,"yyyy-mm-dd") -> C002-2025-04-21 | G4: =IF(COUNTIF($F$2:$F$42,F4)>1, "Duplicate", "Ok") -> Ok | H4: =IF(B4 =VLOOKUP($A4,$A$2:$B$42,2,FALSE), "OK", "Mismatch") -> Mismatch | I4: =IF(C4>E4, "Inconsistent", "OK") -> OK
A5: C004 | B5: Reza Shop | C5: 45916 | D5: 1200000 | E5: 45947 | F5: =$A5&"-"&TEXT( $C5,"yyyy-mm-dd") -> C004-2025-09-16 | G5: =IF(COUNTIF($F$2:$F$42,F5)>1, "Duplicate", "Ok") -> Ok | H5: =IF(B5 =VLOOKUP($A5,$A$2:$B$42,2,FALSE), "OK", "Mismatch") -> OK | I5: =IF(C5>E5, "Inconsistent", "OK") -> OK
A6: C004 | B6: Reza Shop | C6: 45740 | D6: 1200000 | E6: 45986 | F6: =$A6&"-"&TEXT( $C6,"yyyy-mm-dd") -> C004-2025-03-24 | G6: =IF(COUNTIF($F$2:$F$42,F6)>1, "Duplicate", "Ok") -> Ok | H6: =IF(B6 =VLOOKUP($A6,$A$2:$B$42,2,FALSE), "OK", "Mismatch") -> OK | I6: =IF(C6>E6, "Inconsistent", "OK") -> OK
A7: C005 | B7: Neda Store | C7: 45732 | D7: 50000 | E7: 45899 | F7: =$A7&"-"&TEXT( $C7,"yyyy-mm-dd") -> C005-2025-03-16 | G7: =IF(COUNTIF($F$2:$F$42,F7)>1, "Duplicate", "Ok") -> Ok | H7: =IF(B7 =VLOOKUP($A7,$A$2:$B$42,2,FALSE), "OK", "Mismatch") -> OK | I7: =IF(C7>E7, "Inconsistent", "OK") -> OK
A8: C002 | B8: Sara Market | C8: 45899 | D8: 100000 | E8: 45930 | F8: =$A8&"-"&TEXT( $C8,"yyyy-mm-dd") -> C002-2025-08-30 | G8: =IF(COUNTIF($F$2:$F$42,F8)>1, "Duplicate", "Ok") -> Ok | H8: =IF(B8 =VLOOKUP($A8,$A$2:$B$42,2,FALSE), "OK", "Mismatch") -> OK | I8: =IF(C8>E8, "Inconsistent", "OK") -> OK
A9: C005 | B9: Neda Store | C9: 45754 | D9: 100000 | E9: 45984 | F9: =$A9&"-"&TEXT( $C9,"yyyy-mm-dd") -> C005-2025-04-07 | G9: =IF(COUNTIF($F$2:$F$42,F9)>1, "Duplicate", "Ok") -> Ok | H9: =IF(B9 =VLOOKUP($A9,$A$2:$B$42,2,FALSE), "OK", "Mismatch") -> OK | I9: =IF(C9>E9, "Inconsistent", "OK") -> OK
A10: C002 | B10: Sara Market | C10: 45937 | D10: 700000 | E10: 2025-09-28 | F10: =$A10&"-"&TEXT( $C10,"yyyy-mm-dd") -> C002-2025-10-07 | G10: =IF(COUNTIF($F$2:$F$42,F10)>1, "Duplicate", "Ok") -> Ok | H10: =IF(B10 =VLOOKUP($A10,$A$2:$B$42,2,FALSE), "OK", "Mismatch") -> OK | I10: =IF(C10>E10, "Inconsistent", "OK") -> OK
A11: C003 | B11: Ali Supermarket | C11: 45828 | D11: 50000 | E11: 45921 | F11: =$A11&"-"&TEXT( $C11,"yyyy-mm-dd") -> C003-2025-06-20 | G11: =IF(COUNTIF($F$2:$F$42,F11)>1, "Duplicate", "Ok") -> Ok | H11: =IF(B11 =VLOOKUP($A11,$A$2:$B$42,2,FALSE), "OK", "Mismatch") -> OK | I11: =IF(C11>E11, "Inconsistent", "OK") -> OK
A12: C003 | B12: Ali Supermarket | C12: 45691 | D12: 100000 | E12: 45973 | F12: =$A12&"-"&TEXT( $C12,"yyyy-mm-dd") -> C003-2025-02-03 | G12: =IF(COUNTIF($F$2:$F$42,F12)>1, "Duplicate", "Ok") -> Ok | H12: =IF(B12 =VLOOKUP($A12,$A$2:$B$42,2,FALSE), "OK", "Mismatch") -> OK | I12: =IF(C12>E12, "Inconsistent", "OK") -> OK
A13: C001 | B13: Mahdi Store | C13: 45908 | D13: 100000 | E13: 45937 | F13: =$A13&"-"&TEXT( $C13,"yyyy-mm-dd") -> C001-2025-09-08 | G13: =IF(COUNTIF($F$2:$F$42,F13)>1, "Duplicate", "Ok") -> Ok | H13: =IF(B13 =VLOOKUP($A13,$A$2:$B$42,2,FALSE), "OK", "Mismatch") -> OK | I13: =IF(C13>E13, "Inconsistent", "OK") -> OK
A14: C005 | B14: Neda Store | C14: 45905 | D14: 100000 | E14: 45905 | F14: =$A14&"-"&TEXT( $C14,"yyyy-mm-dd") -> C005-2025-09-05 | G14: =IF(COUNTIF($F$2:$F$42,F14)>1, "Duplicate", "Ok") -> Duplicate | H14: =IF(B14 =VLOOKUP($A14,$A$2:$B$42,2,FALSE), "OK", "Mismatch") -> OK | I14: =IF(C14>E14, "Inconsistent", "OK") -> OK
A15: C004 | B15: Reza Shop | C15: 45692 | D15: 100000 | E15: 2025-09-26 | F15: =$A15&"-"&TEXT( $C15,"yyyy-mm-dd") -> C004-2025-02-04 | G15: =IF(COUNTIF($F$2:$F$42,F15)>1, "Duplicate", "Ok") -> Ok | H15: =IF(B15 =VLOOKUP($A15,$A$2:$B$42,2,FALSE), "OK", "Mismatch") -> OK | I15: =IF(C15>E15, "Inconsistent", "OK") -> OK
A16: C003 | B16: Ali Supermarket | C16: 45718 | D16: 1000000 | E16: 45841 | F16: =$A16&"-"&TEXT( $C16,"yyyy-mm-dd") -> C003-2025-03-02 | G16: =IF(COUNTIF($F$2:$F$42,F16)>1, "Duplicate", "Ok") -> Ok | H16: =IF(B16 =VLOOKUP($A16,$A$2:$B$42,2,FALSE), "OK", "Mismatch") -> OK | I16: =IF(C16>E16, "Inconsistent", "OK") -> OK
A17: C001 | B17: Mahdi Store | C17: 45814 | D17: 70000 | E17: 45898 | F17: =$A17&"-"&TEXT( $C17,"yyyy-mm-dd") -> C001-2025-06-06 | G17: =IF(COUNTIF($F$2:$F$42,F17)>1, "Duplicate", "Ok") -> Ok | H17: =IF(B17 =VLOOKUP($A17,$A$2:$B$42,2,FALSE), "OK", "Mismatch") -> OK | I17: =IF(C17>E17, "Inconsistent", "OK") -> OK
A18: C003 | B18: Ali Supermarket | C18: 45697 | D18: 700000 | E18: 45826 | F18: =$A18&"-"&TEXT( $C18,"yyyy-mm-dd") -> C003-2025-02-09 | G18: =IF(COUNTIF($F$2:$F$42,F18)>1, "Duplicate", "Ok") -> Ok | H18: =IF(B18 =VLOOKUP($A18,$A$2:$B$42,2,FALSE), "OK", "Mismatch") -> OK | I18: =IF(C18>E18, "Inconsistent", "OK") -> OK
A19: C003 | B19: Ali Supermarket | C19: 45795 | D19: 10000 | F19: =$A19&"-"&TEXT( $C19,"yyyy-mm-dd") -> C003-2025-05-18 | G19: =IF(COUNTIF($F$2:$F$42,F19)>1, "Duplicate", "Ok") -> Ok | H19: =IF(B19 =VLOOKUP($A19,$A$2:$B$42,2,FALSE), "OK", "Mismatch") -> OK | I19: =IF(C19>E19, "Inconsistent", "OK") -> Inconsistent
A20: C001 | B20: Mahdi Store | C20: 45873 | D20: 1000000 | E20: 45966 | F20: =$A20&"-"&TEXT( $C20,"yyyy-mm-dd") -> C001-2025-08-04 | G20: =IF(COUNTIF($F$2:$F$42,F20)>1, "Duplicate", "Ok") -> Ok | H20: =IF(B20 =VLOOKUP($A20,$A$2:$B$42,2,FALSE), "OK", "Mismatch") -> OK | I20: =IF(C20>E20, "Inconsistent", "OK") -> OK
A21: C003 | B21: Ali Supermarket | C21: 45947 | D21: 1000000 | E21: 45986 | F21: =$A21&"-"&TEXT( $C21,"yyyy-mm-dd") -> C003-2025-10-17 | G21: =IF(COUNTIF($F$2:$F$42,F21)>1, "Duplicate", "Ok") -> Ok | H21: =IF(B21 =VLOOKUP($A21,$A$2:$B$42,2,FALSE), "OK", "Mismatch") -> OK | I21: =IF(C21>E21, "Inconsistent", "OK") -> OK
A22: C005 | B22: Neda Store | C22: 45905 | D22: 500000 | E22: 2025-09-25 | F22: =$A22&"-"&TEXT( $C22,"yyyy-mm-dd") -> C005-2025-09-05 | G22: =IF(COUNTIF($F$2:$F$42,F22)>1, "Duplicate", "Ok") -> Duplicate | H22: =IF(B22 =VLOOKUP($A22,$A$2:$B$42,2,FALSE), "OK", "Mismatch") -> OK | I22: =IF(C22>E22, "Inconsistent", "OK") -> OK
A23: C005 | B23: Neda Store | C23: 2025-09-24 | D23: 500000 | F23: =$A23&"-"&TEXT( $C23,"yyyy-mm-dd") -> C005-2025-09-24 | G23: =IF(COUNTIF($F$2:$F$42,F23)>1, "Duplicate", "Ok") -> Ok | H23: =IF(B23 =VLOOKUP($A23,$A$2:$B$42,2,FALSE), "OK", "Mismatch") -> OK | I23: =IF(C23>E23, "Inconsistent", "OK") -> Inconsistent
A24: C005 | B24: Neda Store | C24: 45750 | D24: 1000000 | E24: 45933 | F24: =$A24&"-"&TEXT( $C24,"yyyy-mm-dd") -> C005-2025-04-03 | G24: =IF(COUNTIF($F$2:$F$42,F24)>1, "Duplicate", "Ok") -> Ok | H24: =IF(B24 =VLOOKUP($A24,$A$2:$B$42,2,FALSE), "OK", "Mismatch") -> OK | I24: =IF(C24>E24, "Inconsistent", "OK") -> OK
A25: C002 | B25: Sara Market | C25: 45984 | D25: 1200000 | E25: 45991 | F25: =$A25&"-"&TEXT( $C25,"yyyy-mm-dd") -> C002-2025-11-23 | G25: =IF(COUNTIF($F$2:$F$42,F25)>1, "Duplicate", "Ok") -> Ok | H25: =IF(B25 =VLOOKUP($A25,$A$2:$B$42,2,FALSE), "OK", "Mismatch") -> OK | I25: =IF(C25>E25, "Inconsistent", "OK") -> OK
A26: C003 | B26: Ali Supermarket | C26: 45843 | D26: 700000 | E26: 45874 | F26: =$A26&"-"&TEXT( $C26,"yyyy-mm-dd") -> C003-2025-07-05 | G26: =IF(COUNTIF($F$2:$F$42,F26)>1, "Duplicate", "Ok") -> Ok | H26: =IF(B26 =VLOOKUP($A26,$A$2:$B$42,2,FALSE), "OK", "Mismatch") -> OK | I26: =IF(C26>E26, "Inconsistent", "OK") -> OK
A27: C005 | B27: Neda Store | C27: 45880 | D27: 1200000 | E27: 45890 | F27: =$A27&"-"&TEXT( $C27,"yyyy-mm-dd") -> C005-2025-08-11 | G27: =IF(COUNTIF($F$2:$F$42,F27)>1, "Duplicate", "Ok") -> Ok | H27: =IF(B27 =VLOOKUP($A27,$A$2:$B$42,2,FALSE), "OK", "Mismatch") -> OK | I27: =IF(C27>E27, "Inconsistent", "OK") -> OK
A28: C002 | B28: Sara Market | C28: 45821 | D28: 120000 | E28: 45913 | F28: =$A28&"-"&TEXT( $C28,"yyyy-mm-dd") -> C002-2025-06-13 | G28: =IF(COUNTIF($F$2:$F$42,F28)>1, "Duplicate", "Ok") -> Ok | H28: =IF(B28 =VLOOKUP($A28,$A$2:$B$42,2,FALSE), "OK", "Mismatch") -> OK | I28: =IF(C28>E28, "Inconsistent", "OK") -> OK
A29: C001 | B29: Mahdi Store | C29: 45674 | D29: 1200000 | E29: 45918 | F29: =$A29&"-"&TEXT( $C29,"yyyy-mm-dd") -> C001-2025-01-17 | G29: =IF(COUNTIF($F$2:$F$42,F29)>1, "Duplicate", "Ok") -> Ok | H29: =IF(B29 =VLOOKUP($A29,$A$2:$B$42,2,FALSE), "OK", "Mismatch") -> OK | I29: =IF(C29>E29, "Inconsistent", "OK") -> OK
A30: C001 | B30: Mahdi Store | C30: 45915 | D30: 100000 | E30: 45916 | F30: =$A30&"-"&TEXT( $C30,"yyyy-mm-dd") -> C001-2025-09-15 | G30: =IF(COUNTIF($F$2:$F$42,F30)>1, "Duplicate", "Ok") -> Ok | H30: =IF(B30 =VLOOKUP($A30,$A$2:$B$42,2,FALSE), "OK", "Mismatch") -> OK | I30: =IF(C30>E30, "Inconsistent", "OK") -> OK
A31: C003 | B31: Ali Supermarket | C31: 45882 | D31: 1000000 | E31: 45914 | F31: =$A31&"-"&TEXT( $C31,"yyyy-mm-dd") -> C003-2025-08-13 | G31: =IF(COUNTIF($F$2:$F$42,F31)>1, "Duplicate", "Ok") -> Ok | H31: =IF(B31 =VLOOKUP($A31,$A$2:$B$42,2,FALSE), "OK", "Mismatch") -> OK | I31: =IF(C31>E31, "Inconsistent", "OK") -> OK
A32: C003 | B32: Neda Store | C32: 45770 | D32: 1000000 | E32: 45955 | F32: =$A32&"-"&TEXT( $C32,"yyyy-mm-dd") -> C003-2025-04-23 | G32: =IF(COUNTIF($F$2:$F$42,F32)>1, "Duplicate", "Ok") -> Ok | H32: =IF(B32 =VLOOKUP($A32,$A$2:$B$42,2,FALSE), "OK", "Mismatch") -> Mismatch | I32: =IF(C32>E32, "Inconsistent", "OK") -> OK
A33: C005 | B33: Neda Store | C33: 45713 | D33: 500000 | E33: 45956 | F33: =$A33&"-"&TEXT( $C33,"yyyy-mm-dd") -> C005-2025-02-25 | G33: =IF(COUNTIF($F$2:$F$42,F33)>1, "Duplicate", "Ok") -> Ok | H33: =IF(B33 =VLOOKUP($A33,$A$2:$B$42,2,FALSE), "OK", "Mismatch") -> OK | I33: =IF(C33>E33, "Inconsistent", "OK") -> OK
A34: C005 | B34: Neda Store | C34: 45923 | D34: 70000 | F34: =$A34&"-"&TEXT( $C34,"yyyy-mm-dd") -> C005-2025-09-23 | G34: =IF(COUNTIF($F$2:$F$42,F34)>1, "Duplicate", "Ok") -> Ok | H34: =IF(B34 =VLOOKUP($A34,$A$2:$B$42,2,FALSE), "OK", "Mismatch") -> OK | I34: =IF(C34>E34, "Inconsistent", "OK") -> Inconsistent
A35: C005 | B35: Neda Store | C35: 45958 | D35: 1000000 | E35: 45989 | F35: =$A35&"-"&TEXT( $C35,"yyyy-mm-dd") -> C005-2025-10-28 | G35: =IF(COUNTIF($F$2:$F$42,F35)>1, "Duplicate", "Ok") -> Ok | H35: =IF(B35 =VLOOKUP($A35,$A$2:$B$42,2,FALSE), "OK", "Mismatch") -> OK | I35: =IF(C35>E35, "Inconsistent", "OK") -> OK
A36: C002 | B36: Sara Market | C36: 45851 | D36: 1200000 | E36: 45876 | F36: =$A36&"-"&TEXT( $C36,"yyyy-mm-dd") -> C002-2025-07-13 | G36: =IF(COUNTIF($F$2:$F$42,F36)>1, "Duplicate", "Ok") -> Ok | H36: =IF(B36 =VLOOKUP($A36,$A$2:$B$42,2,FALSE), "OK", "Mismatch") -> OK | I36: =IF(C36>E36, "Inconsistent", "OK") -> OK
A37: C003 | B37: Ali Supermarket | C37: 45965 | D37: 700000 | E37: 45979 | F37: =$A37&"-"&TEXT( $C37,"yyyy-mm-dd") -> C003-2025-11-04 | G37: =IF(COUNTIF($F$2:$F$42,F37)>1, "Duplicate", "Ok") -> Ok | H37: =IF(B37 =VLOOKUP($A37,$A$2:$B$42,2,FALSE), "OK", "Mismatch") -> OK | I37: =IF(C37>E37, "Inconsistent", "OK") -> OK
A38: C005 | B38: Neda Store | C38: 45882 | D38: 1200000 | E38: 45950 | F38: =$A38&"-"&TEXT( $C38,"yyyy-mm-dd") -> C005-2025-08-13 | G38: =IF(COUNTIF($F$2:$F$42,F38)>1, "Duplicate", "Ok") -> Ok | H38: =IF(B38 =VLOOKUP($A38,$A$2:$B$42,2,FALSE), "OK", "Mismatch") -> OK | I38: =IF(C38>E38, "Inconsistent", "OK") -> OK
A39: C002 | B39: Sara Market | C39: 45909 | D39: 120000 | E39: 45974 | F39: =$A39&"-"&TEXT( $C39,"yyyy-mm-dd") -> C002-2025-09-09 | G39: =IF(COUNTIF($F$2:$F$42,F39)>1, "Duplicate", "Ok") -> Ok | H39: =IF(B39 =VLOOKUP($A39,$A$2:$B$42,2,FALSE), "OK", "Mismatch") -> OK | I39: =IF(C39>E39, "Inconsistent", "OK") -> OK
A40: C001 | B40: Ali Supermarket | C40: 45885 | D40: 1200000 | E40: 45948 | F40: =$A40&"-"&TEXT( $C40,"yyyy-mm-dd") -> C001-2025-08-16 | G40: =IF(COUNTIF($F$2:$F$42,F40)>1, "Duplicate", "Ok") -> Ok | H40: =IF(B40 =VLOOKUP($A40,$A$2:$B$42,2,FALSE), "OK", "Mismatch") -> Mismatch | I40: =IF(C40>E40, "Inconsistent", "OK") -> OK
...

Sheet 3.Raw Data_sort
A1: RowID | B1: CustomerID | C1: CustomerName | D1: InvoiceDate | E1: Amount_IRR | F1: PaymentDate | G1: Notes | H1: CheckKey-1 | I1: Check_invice | J1: CheckIDName | K1: CheckPaymentData
A2: =ROW()-1 -> 1 | B2: C001 | C2: Mahdi Store | D2: 45908 | E2: 100000 | F2: 45937 | H2: =$B2&"-"&TEXT( $D2,"yyyy-mm-dd") -> C001-2025-09-08 | I2: =IF(COUNTIF($H$2:$H$52,H2)>1, "Duplicate", "Ok") -> Ok | J2: =IF(C2 =VLOOKUP($B2,$B$2:$C$52,2,FALSE), "OK", "Mismatch") -> OK | K2: =IF(D2>F2, "Inconsistent", "OK") -> OK
A3: =ROW()-1 -> 2 | B3: C001 | C3: Mahdi Store | D3: 45814 | E3: 70000 | F3: 45898 | H3: =$B3&"-"&TEXT( $D3,"yyyy-mm-dd") -> C001-2025-06-06 | I3: =IF(COUNTIF($H$2:$H$52,H3)>1, "Duplicate", "Ok") -> Ok | J3: =IF(C3 =VLOOKUP($B3,$B$2:$C$52,2,FALSE), "OK", "Mismatch") -> OK | K3: =IF(D3>F3, "Inconsistent", "OK") -> OK
A4: =ROW()-1 -> 3 | B4: C001 | C4: Mahdi Store | D4: 45873 | E4: 1000000 | F4: 45966 | H4: =$B4&"-"&TEXT( $D4,"yyyy-mm-dd") -> C001-2025-08-04 | I4: =IF(COUNTIF($H$2:$H$52,H4)>1, "Duplicate", "Ok") -> Ok | J4: =IF(C4 =VLOOKUP($B4,$B$2:$C$52,2,FALSE), "OK", "Mismatch") -> OK | K4: =IF(D4>F4, "Inconsistent", "OK") -> OK
A5: =ROW()-1 -> 4 | B5: C001 | C5: Mahdi Store | D5: 45674 | E5: 1200000 | F5: 45918 | H5: =$B5&"-"&TEXT( $D5,"yyyy-mm-dd") -> C001-2025-01-17 | I5: =IF(COUNTIF($H$2:$H$52,H5)>1, "Duplicate", "Ok") -> Ok | J5: =IF(C5 =VLOOKUP($B5,$B$2:$C$52,2,FALSE), "OK", "Mismatch") -> OK | K5: =IF(D5>F5, "Inconsistent", "OK") -> OK
A6: =ROW()-1 -> 5 | B6: C001 | C6: Mahdi Store | D6: 45915 | E6: 100000 | F6: 45916 | H6: =$B6&"-"&TEXT( $D6,"yyyy-mm-dd") -> C001-2025-09-15 | I6: =IF(COUNTIF($H$2:$H$52,H6)>1, "Duplicate", "Ok") -> Ok | J6: =IF(C6 =VLOOKUP($B6,$B$2:$C$52,2,FALSE), "OK", "Mismatch") -> OK | K6: =IF(D6>F6, "Inconsistent", "OK") -> OK
A7: =ROW()-1 -> 6 | B7: C001 | C7: Ali Supermarket | D7: 45885 | E7: 1200000 | F7: 45948 | H7: =$B7&"-"&TEXT( $D7,"yyyy-mm-dd") -> C001-2025-08-16 | I7: =IF(COUNTIF($H$2:$H$52,H7)>1, "Duplicate", "Ok") -> Ok | J7: =IF(C7 =VLOOKUP($B7,$B$2:$C$52,2,FALSE), "OK", "Mismatch") -> Mismatch | K7: =IF(D7>F7, "Inconsistent", "OK") -> OK
A8: =ROW()-1 -> 7 | B8: C001 | C8: Mahdi Store | D8: 45782 | E8: 100000 | F8: 45976 | H8: =$B8&"-"&TEXT( $D8,"yyyy-mm-dd") -> C001-2025-05-05 | I8: =IF(COUNTIF($H$2:$H$52,H8)>1, "Duplicate", "Ok") -> Ok | J8: =IF(C8 =VLOOKUP($B8,$B$2:$C$52,2,FALSE), "OK", "Mismatch") -> OK | K8: =IF(D8>F8, "Inconsistent", "OK") -> OK
A9: =ROW()-1 -> 8 | B9: C001 | C9: Mahdi Store | D9: 45929 | E9: 1000000 | F9: 45929 | H9: =$B9&"-"&TEXT( $D9,"yyyy-mm-dd") -> C001-2025-09-29 | I9: =IF(COUNTIF($H$2:$H$52,H9)>1, "Duplicate", "Ok") -> Ok | J9: =IF(C9 =VLOOKUP($B9,$B$2:$C$52,2,FALSE), "OK", "Mismatch") -> OK | K9: =IF(D9>F9, "Inconsistent", "OK") -> OK
A10: =ROW()-1 -> 9 | B10: C001 | C10: Mahdi Store | D10: 45743 | E10: 1200000 | F10: 45988 | H10: =$B10&"-"&TEXT( $D10,"yyyy-mm-dd") -> C001-2025-03-27 | I10: =IF(COUNTIF($H$2:$H$52,H10)>1, "Duplicate", "Ok") -> Ok | J10: =IF(C10 =VLOOKUP($B10,$B$2:$C$52,2,FALSE), "OK", "Mismatch") -> OK | K10: =IF(D10>F10, "Inconsistent", "OK") -> OK
A11: =ROW()-1 -> 10 | B11: C002 | C11: Sara Market | D11: 45677 | E11: 500000 | F11: 45958 | G11: N/A | H11: =$B11&"-"&TEXT( $D11,"yyyy-mm-dd") -> C002-2025-01-20 | I11: =IF(COUNTIF($H$2:$H$52,H11)>1, "Duplicate", "Ok") -> Ok | J11: =IF(C11 =VLOOKUP($B11,$B$2:$C$52,2,FALSE), "OK", "Mismatch") -> OK | K11: =IF(D11>F11, "Inconsistent", "OK") -> OK
A12: =ROW()-1 -> 11 | B12: C002 | C12: Sara Market | D12: 2025-09-03 | E12: 100000 | F12: 45904 | H12: =$B12&"-"&TEXT( $D12,"yyyy-mm-dd") -> C002-2025-09-03 | I12: =IF(COUNTIF($H$2:$H$52,H12)>1, "Duplicate", "Ok") -> Ok | J12: =IF(C12 =VLOOKUP($B12,$B$2:$C$52,2,FALSE), "OK", "Mismatch") -> OK | K12: =IF(D12>F12, "Inconsistent", "OK") -> Inconsistent
A13: =ROW()-1 -> 12 | B13: C002 | C13: Reza Shop | D13: 45768 | E13: 1200000 | F13: 45891 | H13: =$B13&"-"&TEXT( $D13,"yyyy-mm-dd") -> C002-2025-04-21 | I13: =IF(COUNTIF($H$2:$H$52,H13)>1, "Duplicate", "Ok") -> Ok | J13: =IF(C13 =VLOOKUP($B13,$B$2:$C$52,2,FALSE), "OK", "Mismatch") -> Mismatch | K13: =IF(D13>F13, "Inconsistent", "OK") -> OK
A14: =ROW()-1 -> 13 | B14: C002 | C14: Sara Market | D14: 45899 | E14: 100000 | F14: 45930 | H14: =$B14&"-"&TEXT( $D14,"yyyy-mm-dd") -> C002-2025-08-30 | I14: =IF(COUNTIF($H$2:$H$52,H14)>1, "Duplicate", "Ok") -> Ok | J14: =IF(C14 =VLOOKUP($B14,$B$2:$C$52,2,FALSE), "OK", "Mismatch") -> OK | K14: =IF(D14>F14, "Inconsistent", "OK") -> OK
A15: =ROW()-1 -> 14 | B15: C002 | C15: Sara Market | D15: 45937 | E15: 700000 | F15: 45989 | H15: =$B15&"-"&TEXT( $D15,"yyyy-mm-dd") -> C002-2025-10-07 | I15: =IF(COUNTIF($H$2:$H$52,H15)>1, "Duplicate", "Ok") -> Ok | J15: =IF(C15 =VLOOKUP($B15,$B$2:$C$52,2,FALSE), "OK", "Mismatch") -> OK | K15: =IF(D15>F15, "Inconsistent", "OK") -> OK
A16: =ROW()-1 -> 15 | B16: C002 | C16: Sara Market | D16: 45984 | E16: 1200000 | F16: 45991 | H16: =$B16&"-"&TEXT( $D16,"yyyy-mm-dd") -> C002-2025-11-23 | I16: =IF(COUNTIF($H$2:$H$52,H16)>1, "Duplicate", "Ok") -> Ok | J16: =IF(C16 =VLOOKUP($B16,$B$2:$C$52,2,FALSE), "OK", "Mismatch") -> OK | K16: =IF(D16>F16, "Inconsistent", "OK") -> OK
A17: =ROW()-1 -> 16 | B17: C002 | C17: Sara Market | D17: 45821 | E17: 120000 | F17: 45913 | H17: =$B17&"-"&TEXT( $D17,"yyyy-mm-dd") -> C002-2025-06-13 | I17: =IF(COUNTIF($H$2:$H$52,H17)>1, "Duplicate", "Ok") -> Ok | J17: =IF(C17 =VLOOKUP($B17,$B$2:$C$52,2,FALSE), "OK", "Mismatch") -> OK | K17: =IF(D17>F17, "Inconsistent", "OK") -> OK
A18: =ROW()-1 -> 17 | B18: C002 | C18: Sara Market | D18: 45851 | E18: 1200000 | F18: 45876 | H18: =$B18&"-"&TEXT( $D18,"yyyy-mm-dd") -> C002-2025-07-13 | I18: =IF(COUNTIF($H$2:$H$52,H18)>1, "Duplicate", "Ok") -> Ok | J18: =IF(C18 =VLOOKUP($B18,$B$2:$C$52,2,FALSE), "OK", "Mismatch") -> OK | K18: =IF(D18>F18, "Inconsistent", "OK") -> OK
A19: =ROW()-1 -> 18 | B19: C002 | C19: Sara Market | D19: 45909 | E19: 120000 | F19: 45975 | H19: =$B19&"-"&TEXT( $D19,"yyyy-mm-dd") -> C002-2025-09-09 | I19: =IF(COUNTIF($H$2:$H$52,H19)>1, "Duplicate", "Ok") -> Ok | J19: =IF(C19 =VLOOKUP($B19,$B$2:$C$52,2,FALSE), "OK", "Mismatch") -> OK | K19: =IF(D19>F19, "Inconsistent", "OK") -> OK
A20: =ROW()-1 -> 19 | B20: C002 | C20: Sara Market | D20: 45891 | E20: 1200000 | F20: 45922 | H20: =$B20&"-"&TEXT( $D20,"yyyy-mm-dd") -> C002-2025-08-22 | I20: =IF(COUNTIF($H$2:$H$52,H20)>1, "Duplicate", "Ok") -> Ok | J20: =IF(C20 =VLOOKUP($B20,$B$2:$C$52,2,FALSE), "OK", "Mismatch") -> OK | K20: =IF(D20>F20, "Inconsistent", "OK") -> OK
A21: =ROW()-1 -> 20 | B21: C002 | C21: Sara Market | D21: 45786 | E21: 120000 | F21: 45974 | H21: =$B21&"-"&TEXT( $D21,"yyyy-mm-dd") -> C002-2025-05-09 | I21: =IF(COUNTIF($H$2:$H$52,H21)>1, "Duplicate", "Ok") -> Ok | J21: =IF(C21 =VLOOKUP($B21,$B$2:$C$52,2,FALSE), "OK", "Mismatch") -> OK | K21: =IF(D21>F21, "Inconsistent", "OK") -> OK
A22: =ROW()-1 -> 21 | B22: C003 | C22: Ali Supermarket | D22: 45828 | E22: 50000 | F22: 45921 | H22: =$B22&"-"&TEXT( $D22,"yyyy-mm-dd") -> C003-2025-06-20 | I22: =IF(COUNTIF($H$2:$H$52,H22)>1, "Duplicate", "Ok") -> Ok | J22: =IF(C22 =VLOOKUP($B22,$B$2:$C$52,2,FALSE), "OK", "Mismatch") -> OK | K22: =IF(D22>F22, "Inconsistent", "OK") -> OK
A23: =ROW()-1 -> 22 | B23: C003 | C23: Ali Supermarket | D23: 45691 | E23: 100000 | F23: 45973 | H23: =$B23&"-"&TEXT( $D23,"yyyy-mm-dd") -> C003-2025-02-03 | I23: =IF(COUNTIF($H$2:$H$52,H23)>1, "Duplicate", "Ok") -> Ok | J23: =IF(C23 =VLOOKUP($B23,$B$2:$C$52,2,FALSE), "OK", "Mismatch") -> OK | K23: =IF(D23>F23, "Inconsistent", "OK") -> OK
A24: =ROW()-1 -> 23 | B24: C003 | C24: Ali Supermarket | D24: 45718 | E24: 1000000 | F24: 45841 | H24: =$B24&"-"&TEXT( $D24,"yyyy-mm-dd") -> C003-2025-03-02 | I24: =IF(COUNTIF($H$2:$H$52,H24)>1, "Duplicate", "Ok") -> Ok | J24: =IF(C24 =VLOOKUP($B24,$B$2:$C$52,2,FALSE), "OK", "Mismatch") -> OK | K24: =IF(D24>F24, "Inconsistent", "OK") -> OK
A25: =ROW()-1 -> 24 | B25: C003 | C25: Ali Supermarket | D25: 45697 | E25: 700000 | F25: 45826 | H25: =$B25&"-"&TEXT( $D25,"yyyy-mm-dd") -> C003-2025-02-09 | I25: =IF(COUNTIF($H$2:$H$52,H25)>1, "Duplicate", "Ok") -> Ok | J25: =IF(C25 =VLOOKUP($B25,$B$2:$C$52,2,FALSE), "OK", "Mismatch") -> OK | K25: =IF(D25>F25, "Inconsistent", "OK") -> OK
A26: =ROW()-1 -> 25 | B26: C003 | C26: Ali Supermarket | D26: 45795 | E26: 10000 | H26: =$B26&"-"&TEXT( $D26,"yyyy-mm-dd") -> C003-2025-05-18 | I26: =IF(COUNTIF($H$2:$H$52,H26)>1, "Duplicate", "Ok") -> Ok | J26: =IF(C26 =VLOOKUP($B26,$B$2:$C$52,2,FALSE), "OK", "Mismatch") -> OK | K26: =IF(D26>F26, "Inconsistent", "OK") -> Inconsistent
A27: =ROW()-1 -> 26 | B27: C003 | C27: Ali Supermarket | D27: 45947 | E27: 1000000 | F27: 45986 | H27: =$B27&"-"&TEXT( $D27,"yyyy-mm-dd") -> C003-2025-10-17 | I27: =IF(COUNTIF($H$2:$H$52,H27)>1, "Duplicate", "Ok") -> Ok | J27: =IF(C27 =VLOOKUP($B27,$B$2:$C$52,2,FALSE), "OK", "Mismatch") -> OK | K27: =IF(D27>F27, "Inconsistent", "OK") -> OK
A28: =ROW()-1 -> 27 | B28: C003 | C28: Ali Supermarket | D28: 45843 | E28: 700000 | F28: 45874 | H28: =$B28&"-"&TEXT( $D28,"yyyy-mm-dd") -> C003-2025-07-05 | I28: =IF(COUNTIF($H$2:$H$52,H28)>1, "Duplicate", "Ok") -> Ok | J28: =IF(C28 =VLOOKUP($B28,$B$2:$C$52,2,FALSE), "OK", "Mismatch") -> OK | K28: =IF(D28>F28, "Inconsistent", "OK") -> OK
A29: =ROW()-1 -> 28 | B29: C003 | C29: Ali Supermarket | D29: 45882 | E29: 1000000 | F29: 45914 | H29: =$B29&"-"&TEXT( $D29,"yyyy-mm-dd") -> C003-2025-08-13 | I29: =IF(COUNTIF($H$2:$H$52,H29)>1, "Duplicate", "Ok") -> Ok | J29: =IF(C29 =VLOOKUP($B29,$B$2:$C$52,2,FALSE), "OK", "Mismatch") -> OK | K29: =IF(D29>F29, "Inconsistent", "OK") -> OK
A30: =ROW()-1 -> 29 | B30: C003 | C30: Neda Store | D30: 45770 | E30: 1000000 | F30: 45955 | G30: Test | H30: =$B30&"-"&TEXT( $D30,"yyyy-mm-dd") -> C003-2025-04-23 | I30: =IF(COUNTIF($H$2:$H$52,H30)>1, "Duplicate", "Ok") -> Ok | J30: =IF(C30 =VLOOKUP($B30,$B$2:$C$52,2,FALSE), "OK", "Mismatch") -> Mismatch | K30: =IF(D30>F30, "Inconsistent", "OK") -> OK
A31: =ROW()-1 -> 30 | B31: C003 | C31: Ali Supermarket | D31: 45965 | E31: 700000 | F31: 45979 | H31: =$B31&"-"&TEXT( $D31,"yyyy-mm-dd") -> C003-2025-11-04 | I31: =IF(COUNTIF($H$2:$H$52,H31)>1, "Duplicate", "Ok") -> Ok | J31: =IF(C31 =VLOOKUP($B31,$B$2:$C$52,2,FALSE), "OK", "Mismatch") -> OK | K31: =IF(D31>F31, "Inconsistent", "OK") -> OK
A32: =ROW()-1 -> 31 | B32: C003 | C32: Ali Supermarket | D32: 45682 | E32: 1000000 | F32: 45926 | H32: =$B32&"-"&TEXT( $D32,"yyyy-mm-dd") -> C003-2025-01-25 | I32: =IF(COUNTIF($H$2:$H$52,H32)>1, "Duplicate", "Ok") -> Ok | J32: =IF(C32 =VLOOKUP($B32,$B$2:$C$52,2,FALSE), "OK", "Mismatch") -> OK | K32: =IF(D32>F32, "Inconsistent", "OK") -> OK
A33: =ROW()-1 -> 32 | B33: C003 | C33: Ali Supermarket | D33: 45734 | E33: 1000000 | F33: 2025-09-24 | H33: =$B33&"-"&TEXT( $D33,"yyyy-mm-dd") -> C003-2025-03-18 | I33: =IF(COUNTIF($H$2:$H$52,H33)>1, "Duplicate", "Ok") -> Ok | J33: =IF(C33 =VLOOKUP($B33,$B$2:$C$52,2,FALSE), "OK", "Mismatch") -> OK | K33: =IF(D33>F33, "Inconsistent", "OK") -> OK
A34: =ROW()-1 -> 33 | B34: C003 | C34: Ali Supermarket | D34: 45752 | E34: 700000 | F34: 45936 | H34: =$B34&"-"&TEXT( $D34,"yyyy-mm-dd") -> C003-2025-04-05 | I34: =IF(COUNTIF($H$2:$H$52,H34)>1, "Duplicate", "Ok") -> Ok | J34: =IF(C34 =VLOOKUP($B34,$B$2:$C$52,2,FALSE), "OK", "Mismatch") -> OK | K34: =IF(D34>F34, "Inconsistent", "OK") -> OK
A35: =ROW()-1 -> 34 | B35: C004 | C35: Reza Shop | D35: 45916 | E35: 1200000 | F35: 45947 | H35: =$B35&"-"&TEXT( $D35,"yyyy-mm-dd") -> C004-2025-09-16 | I35: =IF(COUNTIF($H$2:$H$52,H35)>1, "Duplicate", "Ok") -> Ok | J35: =IF(C35 =VLOOKUP($B35,$B$2:$C$52,2,FALSE), "OK", "Mismatch") -> OK | K35: =IF(D35>F35, "Inconsistent", "OK") -> OK
A36: =ROW()-1 -> 35 | B36: C004 | C36: Reza Shop | D36: 45740 | E36: 1200000 | F36: 45986 | G36: N/A | H36: =$B36&"-"&TEXT( $D36,"yyyy-mm-dd") -> C004-2025-03-24 | I36: =IF(COUNTIF($H$2:$H$52,H36)>1, "Duplicate", "Ok") -> Ok | J36: =IF(C36 =VLOOKUP($B36,$B$2:$C$52,2,FALSE), "OK", "Mismatch") -> OK | K36: =IF(D36>F36, "Inconsistent", "OK") -> OK
A37: =ROW()-1 -> 36 | B37: C004 | C37: Reza Shop | D37: 45692 | E37: 100000 | F37: 2025-09-26 | H37: =$B37&"-"&TEXT( $D37,"yyyy-mm-dd") -> C004-2025-02-04 | I37: =IF(COUNTIF($H$2:$H$52,H37)>1, "Duplicate", "Ok") -> Ok | J37: =IF(C37 =VLOOKUP($B37,$B$2:$C$52,2,FALSE), "OK", "Mismatch") -> OK | K37: =IF(D37>F37, "Inconsistent", "OK") -> OK
A38: =ROW()-1 -> 37 | B38: C005 | C38: Neda Store | D38: 45732 | E38: 50000 | F38: 45899 | H38: =$B38&"-"&TEXT( $D38,"yyyy-mm-dd") -> C005-2025-03-16 | I38: =IF(COUNTIF($H$2:$H$52,H38)>1, "Duplicate", "Ok") -> Ok | J38: =IF(C38 =VLOOKUP($B38,$B$2:$C$52,2,FALSE), "OK", "Mismatch") -> OK | K38: =IF(D38>F38, "Inconsistent", "OK") -> OK
A39: =ROW()-1 -> 38 | B39: C005 | C39: Neda Store | D39: 45754 | E39: 100000 | F39: 45984 | H39: =$B39&"-"&TEXT( $D39,"yyyy-mm-dd") -> C005-2025-04-07 | I39: =IF(COUNTIF($H$2:$H$52,H39)>1, "Duplicate", "Ok") -> Ok | J39: =IF(C39 =VLOOKUP($B39,$B$2:$C$52,2,FALSE), "OK", "Mismatch") -> OK | K39: =IF(D39>F39, "Inconsistent", "OK") -> OK
A40: =ROW()-1 -> 39 | B40: C005 | C40: Neda Store | D40: 45905 | E40: 100000 | F40: 45905 | H40: =$B40&"-"&TEXT( $D40,"yyyy-mm-dd") -> C005-2025-09-05 | I40: =IF(COUNTIF($H$2:$H$52,H40)>1, "Duplicate", "Ok") -> Duplicate | J40: =IF(C40 =VLOOKUP($B40,$B$2:$C$52,2,FALSE), "OK", "Mismatch") -> OK | K40: =IF(D40>F40, "Inconsistent", "OK") -> OK
...

Sheet 4.Cleaned_Data
A1: RowID | B1: CustomerID | C1: CustomerName | D1: InvoiceDate | E1: Amount_IRR | F1: PaymentDate | G1: Notes | H1: DaysOverDue | I1: AgingBucket | J1: Check_PaymentDate_&_ReportDate | K1: Data_Format_Check | L1: Outdated_Check | M1: Check_InvoiceDate | N1: Duplicate_Invoice | O1: Amount_Validation | P1: ChangeNeeded | Q1: ChangeLog_Status | R1: Check_ColumnO_&_ColumnP_1 | S1: Check_ColumnO_&_ColumnP_2
A2: =ROW()-1 -> 1 | B2: C001 | C2: Mahdi Store | D2: 45908 | E2: 100000 | F2: 45937 | H2: ='5.Report_Info'!$A$2-'4.Cleaned_Data'!$F2 -> 56 | I2: =IF($H2<=30,"0-30 days",IF($H2<=60,"31-60 days", IF($H2<=90, "61-90 days", "91+ days"))) -> 31-60 days | J2: {=TableReport[Report_Date]-TableCleaned[[#This Row],[PaymentDate]]} -> 56 | K2: =IF(AND(ISNUMBER(TableCleaned[[#This Row],[InvoiceDate]]),ISNUMBER(TableCleaned[[#This Row],[PaymentDate]])),"OK","Inconsistent") -> OK | L2: {=IF(ISNUMBER(TableCleaned[[#This Row],[InvoiceDate]]),IF(TableCleaned[[#This Row],[InvoiceDate]]<(TableReport[Report_Date]-120),"Outdated","OK"),"Missing Date")} -> OK | M2: =TableCleaned[[#This Row],[CustomerID]]& " - " & TEXT(TableCleaned[[#This Row],[PaymentDate]],"yyy-mm-dd") -> C001 - 2025-10-07 | N2: =IF(COUNTIF(TableCleaned[Check_InvoiceDate],TableCleaned[[#This Row],[Check_InvoiceDate]])>1, "Duplicate", "OK") -> OK | O2: =IF(OR(ISBLANK(TableCleaned[[#This Row],[Amount_IRR]]),TableCleaned[[#This Row],[Amount_IRR]]<=0), "Invalid(Missing/Negative)", IF(TableCleaned[[#This Row],[Amount_IRR]]>2000000, "Invalid (Too Hiigh)", "OK")) -> OK | P2: =IF(OR(TableCleaned[[#This Row],[Data_Format_Check]]<>"OK",TableCleaned[[#This Row],[Amount_Validation]] <>"OK", IFERROR(TableCleaned[[#This Row],[Outdated_Check]]<>"OK",FALSE),TableCleaned[[#This Row],[Duplicate_Invoice]]<>"OK"), "Changed", "No Change") -> No Change | Q2: =IF(TableCleaned[[#This Row],[ChangeNeeded]]="No Change", "No Change Needed",IF(COUNTIF(TableChangeLog[RowID],TableCleaned[[#This Row],[RowID]])>0, "Logged", "Not Logged")) -> No Change Needed | R2: =COUNTIFS(TableCleaned[[#This Row],[ChangeNeeded]],"Changed",TableCleaned[[#This Row],[ChangeLog_Status]], "Not Logged") -> 0 | S2: =COUNTIFS(TableCleaned[[#This Row],[ChangeNeeded]],"No Changed",TableCleaned[[#This Row],[ChangeLog_Status]], "Logged") -> 0
A3: =ROW()-1 -> 2 | B3: C001 | C3: Mahdi Store | D3: 45814 | E3: 700000 | F3: 45898 | H3: ='5.Report_Info'!$A$2-'4.Cleaned_Data'!$F3 -> 95 | I3: =IF($H3<=30,"0-30 days",IF($H3<=60,"31-60 days", IF($H3<=90, "61-90 days", "91+ days"))) -> 91+ days | J3: {=TableReport[Report_Date]-TableCleaned[[#This Row],[PaymentDate]]} -> 95 | K3: =IF(AND(ISNUMBER(TableCleaned[[#This Row],[InvoiceDate]]),ISNUMBER(TableCleaned[[#This Row],[PaymentDate]])),"OK","Inconsistent") -> OK | L3: {=IF(ISNUMBER(TableCleaned[[#This Row],[InvoiceDate]]),IF(TableCleaned[[#This Row],[InvoiceDate]]<(TableReport[Report_Date]-120),"Outdated","OK"),"Missing Date")} -> Outdated | M3: =TableCleaned[[#This Row],[CustomerID]]& " - " & TEXT(TableCleaned[[#This Row],[PaymentDate]],"yyy-mm-dd") -> C001 - 2025-08-29 | N3: =IF(COUNTIF(TableCleaned[Check_InvoiceDate],TableCleaned[[#This Row],[Check_InvoiceDate]])>1, "Duplicate", "OK") -> OK | O3: =IF(OR(ISBLANK(TableCleaned[[#This Row],[Amount_IRR]]),TableCleaned[[#This Row],[Amount_IRR]]<=0), "Invalid(Missing/Negative)", IF(TableCleaned[[#This Row],[Amount_IRR]]>2000000, "Invalid (Too Hiigh)", "OK")) -> OK | P3: =IF(OR(TableCleaned[[#This Row],[Data_Format_Check]]<>"OK",TableCleaned[[#This Row],[Amount_Validation]] <>"OK", IFERROR(TableCleaned[[#This Row],[Outdated_Check]]<>"OK",FALSE),TableCleaned[[#This Row],[Duplicate_Invoice]]<>"OK"), "Changed", "No Change") -> Changed | Q3: =IF(TableCleaned[[#This Row],[ChangeNeeded]]="No Change", "No Change Needed",IF(COUNTIF(TableChangeLog[RowID],TableCleaned[[#This Row],[RowID]])>0, "Logged", "Not Logged")) -> Not Logged | R3: =COUNTIFS(TableCleaned[[#This Row],[ChangeNeeded]],"Changed",TableCleaned[[#This Row],[ChangeLog_Status]], "Not Logged") -> 1 | S3: =COUNTIFS(TableCleaned[[#This Row],[ChangeNeeded]],"No Changed",TableCleaned[[#This Row],[ChangeLog_Status]], "Logged") -> 0
A4: =ROW()-1 -> 3 | B4: C001 | C4: Mahdi Store | D4: 45873 | E4: 1000000 | F4: 45966 | H4: ='5.Report_Info'!$A$2-'4.Cleaned_Data'!$F4 -> 27 | I4: =IF($H4<=30,"0-30 days",IF($H4<=60,"31-60 days", IF($H4<=90, "61-90 days", "91+ days"))) -> 0-30 days | J4: {=TableReport[Report_Date]-TableCleaned[[#This Row],[PaymentDate]]} -> 27 | K4: =IF(AND(ISNUMBER(TableCleaned[[#This Row],[InvoiceDate]]),ISNUMBER(TableCleaned[[#This Row],[PaymentDate]])),"OK","Inconsistent") -> OK | L4: {=IF(ISNUMBER(TableCleaned[[#This Row],[InvoiceDate]]),IF(TableCleaned[[#This Row],[InvoiceDate]]<(TableReport[Report_Date]-120),"Outdated","OK"),"Missing Date")} -> OK | M4: =TableCleaned[[#This Row],[CustomerID]]& " - " & TEXT(TableCleaned[[#This Row],[PaymentDate]],"yyy-mm-dd") -> C001 - 2025-11-05 | N4: =IF(COUNTIF(TableCleaned[Check_InvoiceDate],TableCleaned[[#This Row],[Check_InvoiceDate]])>1, "Duplicate", "OK") -> OK | O4: =IF(OR(ISBLANK(TableCleaned[[#This Row],[Amount_IRR]]),TableCleaned[[#This Row],[Amount_IRR]]<=0), "Invalid(Missing/Negative)", IF(TableCleaned[[#This Row],[Amount_IRR]]>2000000, "Invalid (Too Hiigh)", "OK")) -> OK | P4: =IF(OR(TableCleaned[[#This Row],[Data_Format_Check]]<>"OK",TableCleaned[[#This Row],[Amount_Validation]] <>"OK", IFERROR(TableCleaned[[#This Row],[Outdated_Check]]<>"OK",FALSE),TableCleaned[[#This Row],[Duplicate_Invoice]]<>"OK"), "Changed", "No Change") -> No Change | Q4: =IF(TableCleaned[[#This Row],[ChangeNeeded]]="No Change", "No Change Needed",IF(COUNTIF(TableChangeLog[RowID],TableCleaned[[#This Row],[RowID]])>0, "Logged", "Not Logged")) -> No Change Needed | R4: =COUNTIFS(TableCleaned[[#This Row],[ChangeNeeded]],"Changed",TableCleaned[[#This Row],[ChangeLog_Status]], "Not Logged") -> 0 | S4: =COUNTIFS(TableCleaned[[#This Row],[ChangeNeeded]],"No Changed",TableCleaned[[#This Row],[ChangeLog_Status]], "Logged") -> 0
A5: =ROW()-1 -> 4 | B5: C001 | C5: Mahdi Store | D5: 45674 | E5: 1200000 | F5: 45918 | H5: ='5.Report_Info'!$A$2-'4.Cleaned_Data'!$F5 -> 75 | I5: =IF($H5<=30,"0-30 days",IF($H5<=60,"31-60 days", IF($H5<=90, "61-90 days", "91+ days"))) -> 61-90 days | J5: {=TableReport[Report_Date]-TableCleaned[[#This Row],[PaymentDate]]} -> 75 | K5: =IF(AND(ISNUMBER(TableCleaned[[#This Row],[InvoiceDate]]),ISNUMBER(TableCleaned[[#This Row],[PaymentDate]])),"OK","Inconsistent") -> OK | L5: {=IF(ISNUMBER(TableCleaned[[#This Row],[InvoiceDate]]),IF(TableCleaned[[#This Row],[InvoiceDate]]<(TableReport[Report_Date]-120),"Outdated","OK"),"Missing Date")} -> Outdated | M5: =TableCleaned[[#This Row],[CustomerID]]& " - " & TEXT(TableCleaned[[#This Row],[PaymentDate]],"yyy-mm-dd") -> C001 - 2025-09-18 | N5: =IF(COUNTIF(TableCleaned[Check_InvoiceDate],TableCleaned[[#This Row],[Check_InvoiceDate]])>1, "Duplicate", "OK") -> OK | O5: =IF(OR(ISBLANK(TableCleaned[[#This Row],[Amount_IRR]]),TableCleaned[[#This Row],[Amount_IRR]]<=0), "Invalid(Missing/Negative)", IF(TableCleaned[[#This Row],[Amount_IRR]]>2000000, "Invalid (Too Hiigh)", "OK")) -> OK | P5: =IF(OR(TableCleaned[[#This Row],[Data_Format_Check]]<>"OK",TableCleaned[[#This Row],[Amount_Validation]] <>"OK", IFERROR(TableCleaned[[#This Row],[Outdated_Check]]<>"OK",FALSE),TableCleaned[[#This Row],[Duplicate_Invoice]]<>"OK"), "Changed", "No Change") -> Changed | Q5: =IF(TableCleaned[[#This Row],[ChangeNeeded]]="No Change", "No Change Needed",IF(COUNTIF(TableChangeLog[RowID],TableCleaned[[#This Row],[RowID]])>0, "Logged", "Not Logged")) -> Not Logged | R5: =COUNTIFS(TableCleaned[[#This Row],[ChangeNeeded]],"Changed",TableCleaned[[#This Row],[ChangeLog_Status]], "Not Logged") -> 1 | S5: =COUNTIFS(TableCleaned[[#This Row],[ChangeNeeded]],"No Changed",TableCleaned[[#This Row],[ChangeLog_Status]], "Logged") -> 0
A6: =ROW()-1 -> 5 | B6: C001 | C6: Mahdi Store | D6: 45915 | E6: 100000 | F6: 45916 | H6: ='5.Report_Info'!$A$2-'4.Cleaned_Data'!$F6 -> 77 | I6: =IF($H6<=30,"0-30 days",IF($H6<=60,"31-60 days", IF($H6<=90, "61-90 days", "91+ days"))) -> 61-90 days | J6: {=TableReport[Report_Date]-TableCleaned[[#This Row],[PaymentDate]]} -> 77 | K6: =IF(AND(ISNUMBER(TableCleaned[[#This Row],[InvoiceDate]]),ISNUMBER(TableCleaned[[#This Row],[PaymentDate]])),"OK","Inconsistent") -> OK | L6: {=IF(ISNUMBER(TableCleaned[[#This Row],[InvoiceDate]]),IF(TableCleaned[[#This Row],[InvoiceDate]]<(TableReport[Report_Date]-120),"Outdated","OK"),"Missing Date")} -> OK | M6: =TableCleaned[[#This Row],[CustomerID]]& " - " & TEXT(TableCleaned[[#This Row],[PaymentDate]],"yyy-mm-dd") -> C001 - 2025-09-16 | N6: =IF(COUNTIF(TableCleaned[Check_InvoiceDate],TableCleaned[[#This Row],[Check_InvoiceDate]])>1, "Duplicate", "OK") -> OK | O6: =IF(OR(ISBLANK(TableCleaned[[#This Row],[Amount_IRR]]),TableCleaned[[#This Row],[Amount_IRR]]<=0), "Invalid(Missing/Negative)", IF(TableCleaned[[#This Row],[Amount_IRR]]>2000000, "Invalid (Too Hiigh)", "OK")) -> OK | P6: =IF(OR(TableCleaned[[#This Row],[Data_Format_Check]]<>"OK",TableCleaned[[#This Row],[Amount_Validation]] <>"OK", IFERROR(TableCleaned[[#This Row],[Outdated_Check]]<>"OK",FALSE),TableCleaned[[#This Row],[Duplicate_Invoice]]<>"OK"), "Changed", "No Change") -> No Change | Q6: =IF(TableCleaned[[#This Row],[ChangeNeeded]]="No Change", "No Change Needed",IF(COUNTIF(TableChangeLog[RowID],TableCleaned[[#This Row],[RowID]])>0, "Logged", "Not Logged")) -> No Change Needed | R6: =COUNTIFS(TableCleaned[[#This Row],[ChangeNeeded]],"Changed",TableCleaned[[#This Row],[ChangeLog_Status]], "Not Logged") -> 0 | S6: =COUNTIFS(TableCleaned[[#This Row],[ChangeNeeded]],"No Changed",TableCleaned[[#This Row],[ChangeLog_Status]], "Logged") -> 0
A7: =ROW()-1 -> 6 | B7: C001 | C7: Mahdi Store | D7: 45885 | E7: 1200000 | F7: 45948 | H7: ='5.Report_Info'!$A$2-'4.Cleaned_Data'!$F7 -> 45 | I7: =IF($H7<=30,"0-30 days",IF($H7<=60,"31-60 days", IF($H7<=90, "61-90 days", "91+ days"))) -> 31-60 days | J7: {=TableReport[Report_Date]-TableCleaned[[#This Row],[PaymentDate]]} -> 45 | K7: =IF(AND(ISNUMBER(TableCleaned[[#This Row],[InvoiceDate]]),ISNUMBER(TableCleaned[[#This Row],[PaymentDate]])),"OK","Inconsistent") -> OK | L7: {=IF(ISNUMBER(TableCleaned[[#This Row],[InvoiceDate]]),IF(TableCleaned[[#This Row],[InvoiceDate]]<(TableReport[Report_Date]-120),"Outdated","OK"),"Missing Date")} -> OK | M7: =TableCleaned[[#This Row],[CustomerID]]& " - " & TEXT(TableCleaned[[#This Row],[PaymentDate]],"yyy-mm-dd") -> C001 - 2025-10-18 | N7: =IF(COUNTIF(TableCleaned[Check_InvoiceDate],TableCleaned[[#This Row],[Check_InvoiceDate]])>1, "Duplicate", "OK") -> OK | O7: =IF(OR(ISBLANK(TableCleaned[[#This Row],[Amount_IRR]]),TableCleaned[[#This Row],[Amount_IRR]]<=0), "Invalid(Missing/Negative)", IF(TableCleaned[[#This Row],[Amount_IRR]]>2000000, "Invalid (Too Hiigh)", "OK")) -> OK | P7: =IF(OR(TableCleaned[[#This Row],[Data_Format_Check]]<>"OK",TableCleaned[[#This Row],[Amount_Validation]] <>"OK", IFERROR(TableCleaned[[#This Row],[Outdated_Check]]<>"OK",FALSE),TableCleaned[[#This Row],[Duplicate_Invoice]]<>"OK"), "Changed", "No Change") -> No Change | Q7: =IF(TableCleaned[[#This Row],[ChangeNeeded]]="No Change", "No Change Needed",IF(COUNTIF(TableChangeLog[RowID],TableCleaned[[#This Row],[RowID]])>0, "Logged", "Not Logged")) -> No Change Needed | R7: =COUNTIFS(TableCleaned[[#This Row],[ChangeNeeded]],"Changed",TableCleaned[[#This Row],[ChangeLog_Status]], "Not Logged") -> 0 | S7: =COUNTIFS(TableCleaned[[#This Row],[ChangeNeeded]],"No Changed",TableCleaned[[#This Row],[ChangeLog_Status]], "Logged") -> 0
A8: =ROW()-1 -> 7 | B8: C001 | C8: Mahdi Store | D8: 45782 | E8: 100000 | F8: 45976 | H8: ='5.Report_Info'!$A$2-'4.Cleaned_Data'!$F8 -> 17 | I8: =IF($H8<=30,"0-30 days",IF($H8<=60,"31-60 days", IF($H8<=90, "61-90 days", "91+ days"))) -> 0-30 days | J8: {=TableReport[Report_Date]-TableCleaned[[#This Row],[PaymentDate]]} -> 17 | K8: =IF(AND(ISNUMBER(TableCleaned[[#This Row],[InvoiceDate]]),ISNUMBER(TableCleaned[[#This Row],[PaymentDate]])),"OK","Inconsistent") -> OK | L8: {=IF(ISNUMBER(TableCleaned[[#This Row],[InvoiceDate]]),IF(TableCleaned[[#This Row],[InvoiceDate]]<(TableReport[Report_Date]-120),"Outdated","OK"),"Missing Date")} -> Outdated | M8: =TableCleaned[[#This Row],[CustomerID]]& " - " & TEXT(TableCleaned[[#This Row],[PaymentDate]],"yyy-mm-dd") -> C001 - 2025-11-15 | N8: =IF(COUNTIF(TableCleaned[Check_InvoiceDate],TableCleaned[[#This Row],[Check_InvoiceDate]])>1, "Duplicate", "OK") -> OK | O8: =IF(OR(ISBLANK(TableCleaned[[#This Row],[Amount_IRR]]),TableCleaned[[#This Row],[Amount_IRR]]<=0), "Invalid(Missing/Negative)", IF(TableCleaned[[#This Row],[Amount_IRR]]>2000000, "Invalid (Too Hiigh)", "OK")) -> OK | P8: =IF(OR(TableCleaned[[#This Row],[Data_Format_Check]]<>"OK",TableCleaned[[#This Row],[Amount_Validation]] <>"OK", IFERROR(TableCleaned[[#This Row],[Outdated_Check]]<>"OK",FALSE),TableCleaned[[#This Row],[Duplicate_Invoice]]<>"OK"), "Changed", "No Change") -> Changed | Q8: =IF(TableCleaned[[#This Row],[ChangeNeeded]]="No Change", "No Change Needed",IF(COUNTIF(TableChangeLog[RowID],TableCleaned[[#This Row],[RowID]])>0, "Logged", "Not Logged")) -> Logged | R8: =COUNTIFS(TableCleaned[[#This Row],[ChangeNeeded]],"Changed",TableCleaned[[#This Row],[ChangeLog_Status]], "Not Logged") -> 0 | S8: =COUNTIFS(TableCleaned[[#This Row],[ChangeNeeded]],"No Changed",TableCleaned[[#This Row],[ChangeLog_Status]], "Logged") -> 0
A9: =ROW()-1 -> 8 | B9: C001 | C9: Mahdi Store | D9: 45929 | E9: 1000000 | F9: 45929 | H9: ='5.Report_Info'!$A$2-'4.Cleaned_Data'!$F9 -> 64 | I9: =IF($H9<=30,"0-30 days",IF($H9<=60,"31-60 days", IF($H9<=90, "61-90 days", "91+ days"))) -> 61-90 days | J9: {=TableReport[Report_Date]-TableCleaned[[#This Row],[PaymentDate]]} -> 64 | K9: =IF(AND(ISNUMBER(TableCleaned[[#This Row],[InvoiceDate]]),ISNUMBER(TableCleaned[[#This Row],[PaymentDate]])),"OK","Inconsistent") -> OK | L9: {=IF(ISNUMBER(TableCleaned[[#This Row],[InvoiceDate]]),IF(TableCleaned[[#This Row],[InvoiceDate]]<(TableReport[Report_Date]-120),"Outdated","OK"),"Missing Date")} -> OK | M9: =TableCleaned[[#This Row],[CustomerID]]& " - " & TEXT(TableCleaned[[#This Row],[PaymentDate]],"yyy-mm-dd") -> C001 - 2025-09-29 | N9: =IF(COUNTIF(TableCleaned[Check_InvoiceDate],TableCleaned[[#This Row],[Check_InvoiceDate]])>1, "Duplicate", "OK") -> OK | O9: =IF(OR(ISBLANK(TableCleaned[[#This Row],[Amount_IRR]]),TableCleaned[[#This Row],[Amount_IRR]]<=0), "Invalid(Missing/Negative)", IF(TableCleaned[[#This Row],[Amount_IRR]]>2000000, "Invalid (Too Hiigh)", "OK")) -> OK | P9: =IF(OR(TableCleaned[[#This Row],[Data_Format_Check]]<>"OK",TableCleaned[[#This Row],[Amount_Validation]] <>"OK", IFERROR(TableCleaned[[#This Row],[Outdated_Check]]<>"OK",FALSE),TableCleaned[[#This Row],[Duplicate_Invoice]]<>"OK"), "Changed", "No Change") -> No Change | Q9: =IF(TableCleaned[[#This Row],[ChangeNeeded]]="No Change", "No Change Needed",IF(COUNTIF(TableChangeLog[RowID],TableCleaned[[#This Row],[RowID]])>0, "Logged", "Not Logged")) -> No Change Needed | R9: =COUNTIFS(TableCleaned[[#This Row],[ChangeNeeded]],"Changed",TableCleaned[[#This Row],[ChangeLog_Status]], "Not Logged") -> 0 | S9: =COUNTIFS(TableCleaned[[#This Row],[ChangeNeeded]],"No Changed",TableCleaned[[#This Row],[ChangeLog_Status]], "Logged") -> 0
A10: =ROW()-1 -> 9 | B10: C001 | C10: Mahdi Store | D10: 45743 | E10: 1200000 | F10: 45988 | H10: ='5.Report_Info'!$A$2-'4.Cleaned_Data'!$F10 -> 5 | I10: =IF($H10<=30,"0-30 days",IF($H10<=60,"31-60 days", IF($H10<=90, "61-90 days", "91+ days"))) -> 0-30 days | J10: {=TableReport[Report_Date]-TableCleaned[[#This Row],[PaymentDate]]} -> 5 | K10: =IF(AND(ISNUMBER(TableCleaned[[#This Row],[InvoiceDate]]),ISNUMBER(TableCleaned[[#This Row],[PaymentDate]])),"OK","Inconsistent") -> OK | L10: {=IF(ISNUMBER(TableCleaned[[#This Row],[InvoiceDate]]),IF(TableCleaned[[#This Row],[InvoiceDate]]<(TableReport[Report_Date]-120),"Outdated","OK"),"Missing Date")} -> Outdated | M10: =TableCleaned[[#This Row],[CustomerID]]& " - " & TEXT(TableCleaned[[#This Row],[PaymentDate]],"yyy-mm-dd") -> C001 - 2025-11-27 | N10: =IF(COUNTIF(TableCleaned[Check_InvoiceDate],TableCleaned[[#This Row],[Check_InvoiceDate]])>1, "Duplicate", "OK") -> OK | O10: =IF(OR(ISBLANK(TableCleaned[[#This Row],[Amount_IRR]]),TableCleaned[[#This Row],[Amount_IRR]]<=0), "Invalid(Missing/Negative)", IF(TableCleaned[[#This Row],[Amount_IRR]]>2000000, "Invalid (Too Hiigh)", "OK")) -> OK | P10: =IF(OR(TableCleaned[[#This Row],[Data_Format_Check]]<>"OK",TableCleaned[[#This Row],[Amount_Validation]] <>"OK", IFERROR(TableCleaned[[#This Row],[Outdated_Check]]<>"OK",FALSE),TableCleaned[[#This Row],[Duplicate_Invoice]]<>"OK"), "Changed", "No Change") -> Changed | Q10: =IF(TableCleaned[[#This Row],[ChangeNeeded]]="No Change", "No Change Needed",IF(COUNTIF(TableChangeLog[RowID],TableCleaned[[#This Row],[RowID]])>0, "Logged", "Not Logged")) -> Not Logged | R10: =COUNTIFS(TableCleaned[[#This Row],[ChangeNeeded]],"Changed",TableCleaned[[#This Row],[ChangeLog_Status]], "Not Logged") -> 1 | S10: =COUNTIFS(TableCleaned[[#This Row],[ChangeNeeded]],"No Changed",TableCleaned[[#This Row],[ChangeLog_Status]], "Logged") -> 0
A11: =ROW()-1 -> 10 | B11: C002 | C11: Sara Market | D11: 45677 | E11: 500000 | F11: 45958 | H11: ='5.Report_Info'!$A$2-'4.Cleaned_Data'!$F11 -> 35 | I11: =IF($H11<=30,"0-30 days",IF($H11<=60,"31-60 days", IF($H11<=90, "61-90 days", "91+ days"))) -> 31-60 days | J11: {=TableReport[Report_Date]-TableCleaned[[#This Row],[PaymentDate]]} -> 35 | K11: =IF(AND(ISNUMBER(TableCleaned[[#This Row],[InvoiceDate]]),ISNUMBER(TableCleaned[[#This Row],[PaymentDate]])),"OK","Inconsistent") -> OK | L11: {=IF(ISNUMBER(TableCleaned[[#This Row],[InvoiceDate]]),IF(TableCleaned[[#This Row],[InvoiceDate]]<(TableReport[Report_Date]-120),"Outdated","OK"),"Missing Date")} -> Outdated | M11: =TableCleaned[[#This Row],[CustomerID]]& " - " & TEXT(TableCleaned[[#This Row],[PaymentDate]],"yyy-mm-dd") -> C002 - 2025-10-28 | N11: =IF(COUNTIF(TableCleaned[Check_InvoiceDate],TableCleaned[[#This Row],[Check_InvoiceDate]])>1, "Duplicate", "OK") -> OK | O11: =IF(OR(ISBLANK(TableCleaned[[#This Row],[Amount_IRR]]),TableCleaned[[#This Row],[Amount_IRR]]<=0), "Invalid(Missing/Negative)", IF(TableCleaned[[#This Row],[Amount_IRR]]>2000000, "Invalid (Too Hiigh)", "OK")) -> OK | P11: =IF(OR(TableCleaned[[#This Row],[Data_Format_Check]]<>"OK",TableCleaned[[#This Row],[Amount_Validation]] <>"OK", IFERROR(TableCleaned[[#This Row],[Outdated_Check]]<>"OK",FALSE),TableCleaned[[#This Row],[Duplicate_Invoice]]<>"OK"), "Changed", "No Change") -> Changed | Q11: =IF(TableCleaned[[#This Row],[ChangeNeeded]]="No Change", "No Change Needed",IF(COUNTIF(TableChangeLog[RowID],TableCleaned[[#This Row],[RowID]])>0, "Logged", "Not Logged")) -> Not Logged | R11: =COUNTIFS(TableCleaned[[#This Row],[ChangeNeeded]],"Changed",TableCleaned[[#This Row],[ChangeLog_Status]], "Not Logged") -> 1 | S11: =COUNTIFS(TableCleaned[[#This Row],[ChangeNeeded]],"No Changed",TableCleaned[[#This Row],[ChangeLog_Status]], "Logged") -> 0
A12: =ROW()-1 -> 11 | B12: C002 | C12: Sara Market | D12: 45903 | E12: 100000 | F12: 45965 | H12: ='5.Report_Info'!$A$2-'4.Cleaned_Data'!$F12 -> 28 | I12: =IF($H12<=30,"0-30 days",IF($H12<=60,"31-60 days", IF($H12<=90, "61-90 days", "91+ days"))) -> 0-30 days | J12: {=TableReport[Report_Date]-TableCleaned[[#This Row],[PaymentDate]]} -> 28 | K12: =IF(AND(ISNUMBER(TableCleaned[[#This Row],[InvoiceDate]]),ISNUMBER(TableCleaned[[#This Row],[PaymentDate]])),"OK","Inconsistent") -> OK | L12: {=IF(ISNUMBER(TableCleaned[[#This Row],[InvoiceDate]]),IF(TableCleaned[[#This Row],[InvoiceDate]]<(TableReport[Report_Date]-120),"Outdated","OK"),"Missing Date")} -> OK | M12: =TableCleaned[[#This Row],[CustomerID]]& " - " & TEXT(TableCleaned[[#This Row],[PaymentDate]],"yyy-mm-dd") -> C002 - 2025-11-04 | N12: =IF(COUNTIF(TableCleaned[Check_InvoiceDate],TableCleaned[[#This Row],[Check_InvoiceDate]])>1, "Duplicate", "OK") -> OK | O12: =IF(OR(ISBLANK(TableCleaned[[#This Row],[Amount_IRR]]),TableCleaned[[#This Row],[Amount_IRR]]<=0), "Invalid(Missing/Negative)", IF(TableCleaned[[#This Row],[Amount_IRR]]>2000000, "Invalid (Too Hiigh)", "OK")) -> OK | P12: =IF(OR(TableCleaned[[#This Row],[Data_Format_Check]]<>"OK",TableCleaned[[#This Row],[Amount_Validation]] <>"OK", IFERROR(TableCleaned[[#This Row],[Outdated_Check]]<>"OK",FALSE),TableCleaned[[#This Row],[Duplicate_Invoice]]<>"OK"), "Changed", "No Change") -> No Change | Q12: =IF(TableCleaned[[#This Row],[ChangeNeeded]]="No Change", "No Change Needed",IF(COUNTIF(TableChangeLog[RowID],TableCleaned[[#This Row],[RowID]])>0, "Logged", "Not Logged")) -> No Change Needed | R12: =COUNTIFS(TableCleaned[[#This Row],[ChangeNeeded]],"Changed",TableCleaned[[#This Row],[ChangeLog_Status]], "Not Logged") -> 0 | S12: =COUNTIFS(TableCleaned[[#This Row],[ChangeNeeded]],"No Changed",TableCleaned[[#This Row],[ChangeLog_Status]], "Logged") -> 0
A13: =ROW()-1 -> 12 | B13: C002 | C13: Sara Market | D13: 45768 | E13: 1200000 | F13: 45891 | H13: ='5.Report_Info'!$A$2-'4.Cleaned_Data'!$F13 -> 102 | I13: =IF($H13<=30,"0-30 days",IF($H13<=60,"31-60 days", IF($H13<=90, "61-90 days", "91+ days"))) -> 91+ days | J13: {=TableReport[Report_Date]-TableCleaned[[#This Row],[PaymentDate]]} -> 102 | K13: =IF(AND(ISNUMBER(TableCleaned[[#This Row],[InvoiceDate]]),ISNUMBER(TableCleaned[[#This Row],[PaymentDate]])),"OK","Inconsistent") -> OK | L13: {=IF(ISNUMBER(TableCleaned[[#This Row],[InvoiceDate]]),IF(TableCleaned[[#This Row],[InvoiceDate]]<(TableReport[Report_Date]-120),"Outdated","OK"),"Missing Date")} -> Outdated | M13: =TableCleaned[[#This Row],[CustomerID]]& " - " & TEXT(TableCleaned[[#This Row],[PaymentDate]],"yyy-mm-dd") -> C002 - 2025-08-22 | N13: =IF(COUNTIF(TableCleaned[Check_InvoiceDate],TableCleaned[[#This Row],[Check_InvoiceDate]])>1, "Duplicate", "OK") -> OK | O13: =IF(OR(ISBLANK(TableCleaned[[#This Row],[Amount_IRR]]),TableCleaned[[#This Row],[Amount_IRR]]<=0), "Invalid(Missing/Negative)", IF(TableCleaned[[#This Row],[Amount_IRR]]>2000000, "Invalid (Too Hiigh)", "OK")) -> OK | P13: =IF(OR(TableCleaned[[#This Row],[Data_Format_Check]]<>"OK",TableCleaned[[#This Row],[Amount_Validation]] <>"OK", IFERROR(TableCleaned[[#This Row],[Outdated_Check]]<>"OK",FALSE),TableCleaned[[#This Row],[Duplicate_Invoice]]<>"OK"), "Changed", "No Change") -> Changed | Q13: =IF(TableCleaned[[#This Row],[ChangeNeeded]]="No Change", "No Change Needed",IF(COUNTIF(TableChangeLog[RowID],TableCleaned[[#This Row],[RowID]])>0, "Logged", "Not Logged")) -> Logged | R13: =COUNTIFS(TableCleaned[[#This Row],[ChangeNeeded]],"Changed",TableCleaned[[#This Row],[ChangeLog_Status]], "Not Logged") -> 0 | S13: =COUNTIFS(TableCleaned[[#This Row],[ChangeNeeded]],"No Changed",TableCleaned[[#This Row],[ChangeLog_Status]], "Logged") -> 0
... A52: =ROW()-1 -> 51 | B52: C005 | C52: Neda Store | D52: 45821 | E52: 1200000 | F52: 45920 | H52: ='5.Report_Info'!$A$2-'4.Cleaned_Data'!$F52 -> 73 | I52: =IF($H52<=30,"0-30 days",IF($H52<=60,"31-60 days", IF($H52<=90, "61-90 days", "91+ days"))) -> 61-90 days | J52: {=TableReport[Report_Date]-TableCleaned[[#This Row],[PaymentDate]]} -> 73 | K52: =IF(AND(ISNUMBER(TableCleaned[[#This Row],[InvoiceDate]]),ISNUMBER(TableCleaned[[#This Row],[PaymentDate]])),"OK","Inconsistent") -> OK | L52: {=IF(ISNUMBER(TableCleaned[[#This Row],[InvoiceDate]]),IF(TableCleaned[[#This Row],[InvoiceDate]]<(TableReport[Report_Date]-120),"Outdated","OK"),"Missing Date")} -> Outdated | M52: =TableCleaned[[#This Row],[CustomerID]]& " - " & TEXT(TableCleaned[[#This Row],[PaymentDate]],"yyy-mm-dd") -> C005 - 2025-09-20 | N52: =IF(COUNTIF(TableCleaned[Check_InvoiceDate],TableCleaned[[#This Row],[Check_InvoiceDate]])>1, "Duplicate", "OK") -> OK | O52: =IF(OR(ISBLANK(TableCleaned[[#This Row],[Amount_IRR]]),TableCleaned[[#This Row],[Amount_IRR]]<=0), "Invalid(Missing/Negative)", IF(TableCleaned[[#This Row],[Amount_IRR]]>2000000, "Invalid (Too Hiigh)", "OK")) -> OK | P52: =IF(OR(TableCleaned[[#This Row],[Data_Format_Check]]<>"OK",TableCleaned[[#This Row],[Amount_Validation]] <>"OK", IFERROR(TableCleaned[[#This Row],[Outdated_Check]]<>"OK",FALSE),TableCleaned[[#This Row],[Duplicate_Invoice]]<>"OK"), "Changed", "No Change") -> Changed | Q52: =IF(TableCleaned[[#This Row],[ChangeNeeded]]="No Change", "No Change Needed",IF(COUNTIF(TableChangeLog[RowID],TableCleaned[[#This Row],[RowID]])>0, "Logged", "Not Logged")) -> Not Logged | R52: =COUNTIFS(TableCleaned[[#This Row],[ChangeNeeded]],"Changed",TableCleaned[[#This Row],[ChangeLog_Status]], "Not Logged") -> 1 | S52: =COUNTIFS(TableCleaned[[#This Row],[ChangeNeeded]],"No Changed",TableCleaned[[#This Row],[ChangeLog_Status]], "Logged") -> 0
E53: =SUBTOTAL(109,TableCleaned[Amount_IRR]) -> 35660000 | I53: =SUBTOTAL(103,TableCleaned[AgingBucket]) -> 51

Sheet 5.Report_Info
A1: Report_Date
A2: 45993

Sheet 6.ChangeLog
A1: ChangeID | B1: RowID | C1: CustomerID | D1: Date | E1: User | F1: Field_Changed | G1: Old_Value | H1: New_Value | I1: Change_Type | J1: Reason for Change
A2: 1 | B2: 3 | C2: C001 | D2: 45962 | E2: Rey | F2: Amount_IRR | G2: 70000 | H2: 700000 | I2: Archived | J2: Fixed invalid data
A3: 2 | B3: 7 | C3: C001 | D3: 45962 | E3: Rey | F3: CustomerName | G3: Ali Supermarket | H3: Mehdi Store | I3: Archived | J3: Correct the customer name from Master file
A4: 3 | B4: 11 | C4: C002 | D4: 45962 | E4: Rey | F4: Notes | G4: N/A | H4: Null | I4: Removed | J4: Removed training data sample left in production | L4: =(COUNTIFS(TableChangeLog[Change_Type], "Archived")+ COUNTIFS(TableChangeLog[Change_Type],"Removed")) -> 18
A5: 4 | B5: 12 | C5: C002 | D5: 45962 | E5: Rey | F5: PaymentDate | G5: 45904 | H5: 45965 | I5: Archived | J5: fixed inconsistent date format
A6: 5 | B6: 13 | C6: C002 | D6: 45962 | E6: Rey | F6: CustomerName | G6: Reza Shop | H6: Sara Market | I6: Archived | J6: Correct the customer name from the Master file
A7: 6 | B7: 14 | C7: C002 | D7: 45962 | E7: Rey | F7: PaymentDate | G7: 45928 | H7: 45989 | I7: Archived | J7: Correct the payment date from the Master file
A8: 7 | B8: 22 | C8: C003 | D8: 45962 | E8: Rey | F8: Amount_IRR | G8: 50000 | H8: 500000 | I8: Archived | J8: Fixed invalid data
A9: 8 | B9: 26 | C9: C003 | D9: 45962 | E9: Rey | F9: Amount_IRR | G9: 10000 | H9: 100000 | I9: Archived | J9: Fixed invalid data
A10: 9 | B10: 26 | C10: C003 | D10: 45962 | E10: Rey | F10: PaymentDate | G10: Null | H10: 45845 | I10: Archived | J10: Added the missing payment date from the Master file
A11: 10 | B11: 30 | C11: C003 | D11: 45962 | E11: Rey | F11: CustomerName | G11: Neda Store | H11: Ali Supermarket | I11: Archived | J11: Correct the customer name from the Master file
A12: 11 | B12: 30 | C12: C003 | D12: 45962 | E12: Rey | F12: Notes | G12: test | H12: Null | I12: Removed | J12: Removed the training data sample left in production
A13: 12 | B13: 36 | C13: C004 | D13: 45962 | E13: Rey | F13: Notes | G13: N/A | H13: Null | I13: Removed | J13: Removed the training data sample left in production
A14: 13 | B14: 38 | C14: C005 | D14: 45962 | E14: Rey | F14: Amount_IRR | G14: 50000 | H14: 500000 | I14: Archived | J14: Fixed invalid data
A15: 14 | B15: 41 | C15: C005 | D15: 45962 | E15: Rey | F15: InvoiceDate | G15: 45905 | H15: 45906 | I15: Archived | J15: Correct the invoice date from the Master file
A16: 15 | B16: 42 | C16: C005 | D16: 45962 | E16: Rey | F16: Notes | G16: N/A | H16: Null | I16: Removed | J16: Removed the training data sample left in production
A17: 16 | B17: 42 | C17: C005 | D17: 45962 | E17: Rey | F17: PaymentDate | G17: Null | H17: 45940 | I17: Archived | J17: Added the missing payment date from the Master file
A18: 17 | B18: 46 | C18: C005 | D18: 45962 | E18: Rey | F18: PaymentDate | G18: Null | H18: 45983 | I18: Archived | J18: Added the missing payment date from the Master file
A19: 18 | B19: 53 | C19: C999 | D19: 45962 | E19: Rey | F19: CustomerID | G19: C999 | H19: Null | I19: Removed | J19: Removed Fixed the missing link between the Accounts Receivable file and the master file

Sheet 7.1Aging_Report
B1: Acount Receivable Aging Report - As of 2025-12-02
B3: Sum of Amount_IRR | C3: Column Labels
B4: CustomerID | C4: 0-30 days | D4: 31-60 days | E4: 61-90 days | F4: 91+ days | G4: Grand Total
B5: C001 | C5: 2300000 | D5: 1300000 | E5: 2300000 | F5: 700000 | G5: 6600000
B6: C002 | C6: 1540000 | D6: 500000 | E6: 2120000 | F6: 2400000 | G6: 6560000
B7: C003 | C7: 1800000 | D7: 1700000 | E7: 3500000 | F7: 2500000 | G7: 9500000
B8: C004 | C8: 1200000 | D8: 1200000 | E8: 100000 | G8: 2500000
B9: C005 | C9: 2800000 | D9: 3700000 | E9: 2300000 | F9: 1700000 | G9: 10500000
B10: Grand Total | C10: 9640000 | D10: 8400000 | E10: 10320000 | F10: 7300000 | G10: 35660000
B11: Dataset: Cleaned AR DataReport Generated by: Financial Analyst

Sheet 7.2 Aging_Report_Final
B1: Aging Report Final
B3: Account Receivable Aging Report - As of 2025-12-02
B4: CustomerID | C4: 0-30 days | D4: 31-60 days | E4: 61-90 days | F4: 91+ days | G4: Grand Total
B5: C001 | C5: 2300000 | D5: 1300000 | E5: 2300000 | F5: 700000 | G5: 6600000
B6: C002 | C6: 1540000 | D6: 500000 | E6: 2120000 | F6: 2400000 | G6: 6560000
B7: C003 | C7: 1800000 | D7: 1700000 | E7: 3500000 | F7: 2500000 | G7: 9500000
B8: C004 | C8: 1200000 | D8: 1200000 | E8: 100000 | G8: 2500000
B9: C005 | C9: 2800000 | D9: 3700000 | E9: 2300000 | F9: 1700000 | G9: 10500000
B10: Grand Total | C10: 9640000 | D10: 8400000 | E10: 10320000 | F10: 7300000 | G10: 35660000
B11: Dataset: Cleaned AR DataReport Generated by: Financial Analyst

Sheet 8.1 Core_Validation_Test
B1: CoreValidation Test
B3: Test Case | C3: Test_Definitions | D3: Category | E3: Formula | F3: Expected | G3: Result | H3: Status | I3: Notes
B4: Invalid Amount(Range Check) | C4: Ensure no negative or zero values | D4: Financial | E4: IF(COUNTIF(TableCleaned[Amount_Validation], "OK")=ROWS(TableCleaned[Amount_Validation]), "OK", "Invalid amount Found") | F4: OK | G4: =IF(COUNTIF(TableCleaned[Amount_Validation], "OK")=ROWS(TableCleaned[Amount_Validation]), "OK", "Invalid amount Found") -> OK | H4: =IF(TableCoreValidation[[#This Row],[Result]]=TableCoreValidation[[#This Row],[Expected]], "Pass", "Fail") -> Pass | I4: Verivied
B5: Duplicate Invoice (CustomerID + Date) | C5: Detects duplicate invoice for same customer/date. | D5: Data Intergrity | E5: IF(COUNTIF(TableCleaned[Duplicate_Invoice],"Duplicate")=0,"OK","Duplicate Fpound") | F5: OK | G5: =IF(COUNTIF(TableCleaned[Duplicate_Invoice],"Duplicate")=0,"OK","Duplicate Found") -> OK | H5: =IF(TableCoreValidation[[#This Row],[Result]]=TableCoreValidation[[#This Row],[Expected]], "Pass", "Fail") -> Pass | I5: Verivied
B6: Date Format Consistency | C6: Check all dates follow yyyy-mm-dd | D6: Data Format | E6: IF(COUNTIF(TableCleaned[Data_Format_Check],"Inconsistent")=0,"OK","Inconsistent") | F6: OK | G6: =IF(COUNTIF(TableCleaned[Data_Format_Check],"Inconsistent")=0,"OK","Inconsistent") -> OK | H6: =IF(TableCoreValidation[[#This Row],[Result]]=TableCoreValidation[[#This Row],[Expected]], "Pass", "Fail") -> Pass | I6: Verivied
B7: Change Needed vs Logged | C7: detects over/logged clean records | D7: Governance | E7: IF(AND(TableCleaned[Check_ColumnO_&_ColumnP_1]=0,TableCleaned[Check_ColumnO_&_ColumnP_2]=0),"OK", "Mismatch") | F7: OK | G7: {=IF(AND(TableCleaned[Check_ColumnO_&_ColumnP_1]=0,TableCleaned[Check_ColumnO_&_ColumnP_2]=0),"OK", "Mismatch")} -> Mismatch | H7: =IF(TableCoreValidation[[#This Row],[Result]]=TableCoreValidation[[#This Row],[Expected]], "Pass", "Fail") -> Fail | I7: 23 Updated records not found in ChangeLog - must be registered manually
B8: Outed Invioce Check (>120) | C8: Detects Invoice older than 120 days | D8: Aging | E8: IF(COUNTIF(TableCleaned[Outdated_Check], "Outdated")=0, "OK", "Outedated Found") | F8: OK | G8: =IF(COUNTIF(TableCleaned[Outdated_Check], "Outdated")=0, "OK", "Outedated Found") -> Outedated Found | H8: =IF(TableCoreValidation[[#This Row],[Result]]=TableCoreValidation[[#This Row],[Expected]], "Pass", "Fail") -> Fail | I8: 29 Invoices older than 120 days- flagged for review
B9: Payment befor Invoice Check | C9: Payment should not occur before invoice date | D9: Data Logic | E9: IF(Cleaned_Data!F2<Cleaned_Data!D2, "Invalid", "OK") | F9: OK | G9: =IF('4.Cleaned_Data'!F2<'4.Cleaned_Data'!D2, "Invalid", "OK") -> OK | H9: =IF(TableCoreValidation[[#This Row],[Result]]=TableCoreValidation[[#This Row],[Expected]], "Pass", "Fail") -> Pass | I9: Verivied
B10: Irrelevant Data Check | C10: Detects test/(N/A) records | D10: Data Quality | E10: IF(SUMPRODUCT(--((TableCleaned[Notes]="Test") + (TableCleaned[Notes]="N/A")))>0, "Irrelevant Found", "OK") | F10: OK | G10: {=IF(SUMPRODUCT(--((TableCleaned[Notes]="Test") + (TableCleaned[Notes]="N/A")))>0, "Irrelevant Found", "OK")} -> OK | H10: =IF(TableCoreValidation[[#This Row],[Result]]=TableCoreValidation[[#This Row],[Expected]], "Pass", "Fail") -> Pass | I10: Verivied
B12: All Test Passed Summary | C12: =IF(COUNTIF(TableCoreValidation[Status],"Fail")=0,"✅ All Tests Passed","❌ Some Tests Failed") -> ❌ Some Tests Failed

Sheet 8.2 Structural_Validation_Test
B1: Structural Validation Test
B3: Test Case | C3: Test_Definitions | D3: Category | E3: Formula | F3: Expected | G3: Result | H3: Status | I3: Notes
B4: Total Amount Match | C4: Verifies Cleaned vs Aging Report totals | D4: Financial | E4: IF(SUM(TableCleaned[Amount_IRR])=GETPIVOTDATA("Amount_IRR",Aging_Report!$A$2),"OK","Mismatch") | F4: OK | G4: =IF(SUM(TableCleaned[Amount_IRR])=GETPIVOTDATA("Amount_IRR",'7.1Aging_Report'!$B$3),"OK","Mismatch") -> OK | H4: =IF(TableStruc.Validation[[#This Row],[Result]]=TableStruc.Validation[[#This Row],[Expected]], "Pass", "Fail") -> Pass | I4: Verified
